order-book/a1-a2-testcases/hard-many-matches-1.in

	# fills up the order book for 10 instruments, then clears it by matching,
	# using 40 clients and up to 10000 orders per instrument
	
40
o
12 S 0 INSTR4 10 114
20 S 1 INSTR4 15 84
27 S 2 INSTR4 19 392
11 S 3 INSTR4 25 195
4 S 4 INSTR4 31 346
5 S 5 INSTR4 36 346
29 S 6 INSTR4 41 347
24 S 7 INSTR4 45 419
19 S 8 INSTR4 49 86
39 S 9 INSTR4 52 213
26 S 10 INSTR4 58 95
13 S 11 INSTR4 61 122
18 S 12 INSTR4 65 119
0 S 13 INSTR4 68 365
6 S 14 INSTR4 73 208
36 S 15 INSTR4 75 343
22 S 16 INSTR4 81 276
38 S 17 INSTR4 83 178
25 S 18 INSTR4 85 375
3 S 19 INSTR4 89 324
15 S 20 INSTR4 93 136
28 S 21 INSTR4 99 382
31 S 22 INSTR4 105 416
7 S 23 INSTR4 107 374
17 S 24 INSTR4 112 301
16 S 25 INSTR4 115 332
2 S 26 INSTR4 119 238
30 S 27 INSTR4 123 263
23 S 28 INSTR4 127 119
34 S 29 INSTR4 131 275
37 S 30 INSTR4 136 387
32 S 31 INSTR4 140 149
8 S 32 INSTR4 146 190
21 S 33 INSTR4 151 338
33 S 34 INSTR4 153 196
1 S 35 INSTR4 156 136
9 S 36 INSTR4 159 327
14 S 37 INSTR4 165 159
35 S 38 INSTR4 167 330
10 S 39 INSTR4 169 260
28 S 40 INSTR4 175 163
26 S 41 INSTR4 178 234
31 S 42 INSTR4 183 386
21 S 43 INSTR4 188 308
32 S 44 INSTR4 194 234
24 S 45 INSTR4 197 384
0 S 46 INSTR4 202 413
12 S 47 INSTR4 204 351
27 S 48 INSTR4 210 81
3 S 49 INSTR4 212 393
14 S 50 INSTR4 218 149
19 S 51 INSTR4 224 409
8 S 52 INSTR4 228 168
18 S 53 INSTR4 231 79
17 S 54 INSTR4 237 273
1 S 55 INSTR4 243 84
16 S 56 INSTR4 249 267
35 S 57 INSTR4 254 107
6 S 58 INSTR4 259 356
38 S 59 INSTR4 263 334
25 S 60 INSTR4 265 326
2 S 61 INSTR4 269 358
30 S 62 INSTR4 275 271
29 S 63 INSTR4 277 179
5 S 64 INSTR4 280 202
13 S 65 INSTR4 284 250
4 S 66 INSTR4 287 111
20 S 67 INSTR4 293 232
9 S 68 INSTR4 297 116
39 S 69 INSTR4 300 166
34 S 70 INSTR4 302 210
37 S 71 INSTR4 307 150
33 S 72 INSTR4 312 133
15 S 73 INSTR4 315 258
10 S 74 INSTR4 317 88
7 S 75 INSTR4 322 380
23 S 76 INSTR4 328 238
22 S 77 INSTR4 332 318
11 S 78 INSTR4 338 342
36 S 79 INSTR4 340 320
1 S 80 INSTR4 343 346
12 S 81 INSTR4 345 304
7 S 82 INSTR4 347 247
38 S 83 INSTR4 349 352
20 S 84 INSTR4 353 354
22 S 85 INSTR4 356 280
21 S 86 INSTR4 361 320
26 S 87 INSTR4 363 373
28 S 88 INSTR4 365 270
23 S 89 INSTR4 371 81
29 S 90 INSTR4 373 280
10 S 91 INSTR4 379 249
18 S 92 INSTR4 382 107
4 S 93 INSTR4 385 227
33 S 94 INSTR4 389 414
34 S 95 INSTR4 394 380
31 S 96 INSTR4 396 300
32 S 97 INSTR4 401 302
24 S 98 INSTR4 404 196
19 S 99 INSTR4 408 328
5 S 100 INSTR4 414 81
14 S 101 INSTR4 417 288
13 S 102 INSTR4 419 362
8 S 103 INSTR4 421 192
36 S 104 INSTR4 425 281
11 S 105 INSTR4 428 112
9 S 106 INSTR4 431 313
16 S 107 INSTR4 436 419
30 S 108 INSTR4 440 387
0 S 109 INSTR4 443 283
37 S 110 INSTR4 447 148
17 S 111 INSTR4 451 74
15 S 112 INSTR4 453 90
25 S 113 INSTR4 457 138
2 S 114 INSTR4 463 234
27 S 115 INSTR4 467 114
35 S 116 INSTR4 469 297
6 S 117 INSTR4 475 103
39 S 118 INSTR4 481 259
3 S 119 INSTR4 483 164
10 S 120 INSTR4 489 246
37 S 121 INSTR4 493 275
6 S 122 INSTR4 498 284
12 S 123 INSTR4 503 259
35 S 124 INSTR4 509 355
28 S 125 INSTR4 511 394
4 S 126 INSTR4 514 412
2 S 127 INSTR4 517 76
3 S 128 INSTR4 519 382
0 S 129 INSTR4 522 259
21 S 130 INSTR4 527 154
16 S 131 INSTR4 531 99
14 S 132 INSTR4 534 399
15 S 133 INSTR4 539 202
23 S 134 INSTR4 544 361
30 S 135 INSTR4 549 297
20 S 136 INSTR4 555 203
36 S 137 INSTR4 557 407
25 S 138 INSTR4 560 281
9 S 139 INSTR4 562 170
11 S 140 INSTR4 566 310
27 S 141 INSTR4 568 76
33 S 142 INSTR4 574 160
26 S 143 INSTR4 580 184
39 S 144 INSTR4 582 326
17 S 145 INSTR4 588 241
24 S 146 INSTR4 594 256
7 S 147 INSTR4 600 359
31 S 148 INSTR4 602 160
19 S 149 INSTR4 607 301
32 S 150 INSTR4 612 203
13 S 151 INSTR4 615 177
8 S 152 INSTR4 620 241
5 S 153 INSTR4 622 207
38 S 154 INSTR4 624 90
29 S 155 INSTR4 627 138
34 S 156 INSTR4 629 409
1 S 157 INSTR4 634 348
22 S 158 INSTR4 637 252
18 S 159 INSTR4 639 76
35 S 160 INSTR4 642 180
14 S 161 INSTR4 646 271
0 S 162 INSTR4 651 349
36 S 163 INSTR4 655 197
2 S 164 INSTR4 661 164
15 S 165 INSTR4 663 420
29 S 166 INSTR4 665 356
9 S 167 INSTR4 671 206
32 S 168 INSTR4 675 145
25 S 169 INSTR4 677 251
22 S 170 INSTR4 682 197
7 S 171 INSTR4 687 84
23 S 172 INSTR4 691 106
27 S 173 INSTR4 697 195
6 S 174 INSTR4 699 217
20 S 175 INSTR4 705 190
39 S 176 INSTR4 707 413
11 S 177 INSTR4 709 238
33 S 178 INSTR4 713 208
10 S 179 INSTR4 715 101
12 S 180 INSTR4 718 111
28 S 181 INSTR4 721 331
8 S 182 INSTR4 724 120
21 S 183 INSTR4 729 324
17 S 184 INSTR4 731 305
26 S 185 INSTR4 737 233
38 S 186 INSTR4 739 299
1 S 187 INSTR4 743 162
30 S 188 INSTR4 746 71
4 S 189 INSTR4 751 391
37 S 190 INSTR4 753 215
19 S 191 INSTR4 758 239
16 S 192 INSTR4 764 83
24 S 193 INSTR4 769 354
3 S 194 INSTR4 775 308
13 S 195 INSTR4 780 413
34 S 196 INSTR4 783 344
18 S 197 INSTR4 785 231
5 S 198 INSTR4 787 269
31 S 199 INSTR4 793 233
33 S 200 INSTR4 799 77
24 S 201 INSTR4 802 379
11 S 202 INSTR4 808 277
6 S 203 INSTR4 812 143
17 S 204 INSTR4 815 192
37 S 205 INSTR4 817 246
29 S 206 INSTR4 823 159
36 S 207 INSTR4 828 373
2 S 208 INSTR4 834 389
0 S 209 INSTR4 837 145
38 S 210 INSTR4 841 417
8 S 211 INSTR4 843 109
14 S 212 INSTR4 848 329
32 S 213 INSTR4 853 155
35 S 214 INSTR4 858 420
30 S 215 INSTR4 862 160
15 S 216 INSTR4 866 137
23 S 217 INSTR4 871 245
9 S 218 INSTR4 876 240
3 S 219 INSTR4 882 344
5 S 220 INSTR4 884 296
28 S 221 INSTR4 888 131
1 S 222 INSTR4 894 403
13 S 223 INSTR4 900 346
16 S 224 INSTR4 902 168
4 S 225 INSTR4 904 188
10 S 226 INSTR4 907 156
27 S 227 INSTR4 912 109
21 S 228 INSTR4 915 181
20 S 229 INSTR4 921 179
19 S 230 INSTR4 924 342
7 S 231 INSTR4 928 409
31 S 232 INSTR4 934 407
12 S 233 INSTR4 939 278
22 S 234 INSTR4 942 183
25 S 235 INSTR4 945 315
39 S 236 INSTR4 950 280
26 S 237 INSTR4 955 151
18 S 238 INSTR4 957 387
34 S 239 INSTR4 959 324
15 S 240 INSTR4 962 85
10 S 241 INSTR4 965 233
37 S 242 INSTR4 971 283
28 S 243 INSTR4 976 257
12 S 244 INSTR4 982 256
6 S 245 INSTR4 985 136
21 S 246 INSTR4 988 349
22 S 247 INSTR4 994 116
3 S 248 INSTR4 996 253
38 S 249 INSTR4 1002 246
35 S 250 INSTR4 1007 219
17 S 251 INSTR4 1011 412
32 S 252 INSTR4 1014 378
24 S 253 INSTR4 1016 75
16 S 254 INSTR4 1022 84
29 S 255 INSTR4 1028 330
34 S 256 INSTR4 1031 83
11 S 257 INSTR4 1034 137
5 S 258 INSTR4 1040 225
19 S 259 INSTR4 1042 244
8 S 260 INSTR4 1046 401
26 S 261 INSTR4 1051 408
2 S 262 INSTR4 1057 195
36 S 263 INSTR4 1063 404
7 S 264 INSTR4 1066 303
27 S 265 INSTR4 1071 418
30 S 266 INSTR4 1075 105
23 S 267 INSTR4 1079 231
20 S 268 INSTR4 1082 153
25 S 269 INSTR4 1085 343
9 S 270 INSTR4 1091 419
31 S 271 INSTR4 1097 198
4 S 272 INSTR4 1101 243
14 S 273 INSTR4 1105 330
13 S 274 INSTR4 1109 296
18 S 275 INSTR4 1111 328
39 S 276 INSTR4 1113 281
33 S 277 INSTR4 1115 367
1 S 278 INSTR4 1119 406
0 S 279 INSTR4 1123 173
24 S 280 INSTR4 1129 355
13 S 281 INSTR4 1134 257
22 S 282 INSTR4 1139 199
36 S 283 INSTR4 1144 415
21 S 284 INSTR4 1146 329
25 S 285 INSTR4 1148 173
29 S 286 INSTR4 1150 389
3 S 287 INSTR4 1156 153
0 S 288 INSTR4 1160 216
1 S 289 INSTR4 1163 101
10 S 290 INSTR4 1167 311
16 S 291 INSTR4 1170 140
17 S 292 INSTR4 1172 190
8 S 293 INSTR4 1174 129
26 S 294 INSTR4 1177 409
11 S 295 INSTR4 1183 241
18 S 296 INSTR4 1185 168
28 S 297 INSTR4 1188 328
37 S 298 INSTR4 1194 112
7 S 299 INSTR4 1200 411
4 S 300 INSTR4 1206 177
23 S 301 INSTR4 1211 159
33 S 302 INSTR4 1217 380
6 S 303 INSTR4 1222 287
38 S 304 INSTR4 1224 113
2 S 305 INSTR4 1229 356
34 S 306 INSTR4 1233 144
14 S 307 INSTR4 1236 252
35 S 308 INSTR4 1240 374
27 S 309 INSTR4 1245 402
15 S 310 INSTR4 1247 234
39 S 311 INSTR4 1250 132
9 S 312 INSTR4 1256 224
5 S 313 INSTR4 1260 154
31 S 314 INSTR4 1264 379
19 S 315 INSTR4 1267 355
30 S 316 INSTR4 1272 372
32 S 317 INSTR4 1276 324
12 S 318 INSTR4 1280 398
20 S 319 INSTR4 1282 86
24 S 320 INSTR4 1284 348
34 S 321 INSTR4 1286 348
7 S 322 INSTR4 1291 125
36 S 323 INSTR4 1295 81
11 S 324 INSTR4 1301 253
2 S 325 INSTR4 1307 413
30 S 326 INSTR4 1309 149
37 S 327 INSTR4 1313 191
35 S 328 INSTR4 1318 214
9 S 329 INSTR4 1321 300
26 S 330 INSTR4 1324 207
10 S 331 INSTR4 1327 112
15 S 332 INSTR4 1331 318
25 S 333 INSTR4 1333 374
