order-book/a1-a2-testcases/hard-multi-exec-cancel-race.in

    # Adds a pair of matchable concurrent orders, cancels them immediately
    # So the exec may or may not happen depending on if the cancels happen first

    # All pairs of threads are also added to the same instrument for added complications
    
40
o
0 B 0 GOOG 2700 1
0 C 0
20 S 1 GOOG 2700 1
20 C 1
1 B 2 GOOG 2700 1
1 C 2
21 S 3 GOOG 2700 1
21 C 3
2 B 4 GOOG 2700 1
2 C 4
22 S 5 GOOG 2700 1
22 C 5
3 B 6 GOOG 2700 1
3 C 6
23 S 7 GOOG 2700 1
23 C 7
4 B 8 GOOG 2700 1
4 C 8
24 S 9 GOOG 2700 1
24 C 9
5 B 10 GOOG 2700 1
5 C 10
25 S 11 GOOG 2700 1
25 C 11
6 B 12 GOOG 2700 1
6 C 12
26 S 13 GOOG 2700 1
26 C 13
7 B 14 GOOG 2700 1
7 C 14
27 S 15 GOOG 2700 1
27 C 15
8 B 16 GOOG 2700 1
8 C 16
28 S 17 GOOG 2700 1
28 C 17
9 B 18 GOOG 2700 1
9 C 18
29 S 19 GOOG 2700 1
29 C 19
10 B 20 GOOG 2700 1
10 C 20
30 S 21 GOOG 2700 1
30 C 21
11 B 22 GOOG 2700 1
11 C 22
31 S 23 GOOG 2700 1
31 C 23
12 B 24 GOOG 2700 1
12 C 24
32 S 25 GOOG 2700 1
32 C 25
13 B 26 GOOG 2700 1
13 C 26
33 S 27 GOOG 2700 1
33 C 27
14 B 28 GOOG 2700 1
14 C 28
34 S 29 GOOG 2700 1
34 C 29
15 B 30 GOOG 2700 1
15 C 30
35 S 31 GOOG 2700 1
35 C 31
16 B 32 GOOG 2700 1
16 C 32
36 S 33 GOOG 2700 1
36 C 33
17 B 34 GOOG 2700 1
17 C 34
37 S 35 GOOG 2700 1
37 C 35
18 B 36 GOOG 2700 1
18 C 36
38 S 37 GOOG 2700 1
38 C 37
19 B 38 GOOG 2700 1
19 C 38
39 S 39 GOOG 2700 1
39 C 39
0 B 40 GOOG 2700 1
0 C 40
20 S 41 GOOG 2700 1
20 C 41
1 B 42 GOOG 2700 1
1 C 42
21 S 43 GOOG 2700 1
21 C 43
2 B 44 GOOG 2700 1
2 C 44
22 S 45 GOOG 2700 1
22 C 45
3 B 46 GOOG 2700 1
3 C 46
23 S 47 GOOG 2700 1
23 C 47
4 B 48 GOOG 2700 1
4 C 48
24 S 49 GOOG 2700 1
24 C 49
5 B 50 GOOG 2700 1
5 C 50
25 S 51 GOOG 2700 1
25 C 51
6 B 52 GOOG 2700 1
6 C 52
26 S 53 GOOG 2700 1
26 C 53
7 B 54 GOOG 2700 1
7 C 54
27 S 55 GOOG 2700 1
27 C 55
8 B 56 GOOG 2700 1
8 C 56
28 S 57 GOOG 2700 1
28 C 57
9 B 58 GOOG 2700 1
9 C 58
29 S 59 GOOG 2700 1
29 C 59
10 B 60 GOOG 2700 1
10 C 60
30 S 61 GOOG 2700 1
30 C 61
11 B 62 GOOG 2700 1
11 C 62
31 S 63 GOOG 2700 1
31 C 63
12 B 64 GOOG 2700 1
12 C 64
32 S 65 GOOG 2700 1
32 C 65
13 B 66 GOOG 2700 1
13 C 66
33 S 67 GOOG 2700 1
33 C 67
14 B 68 GOOG 2700 1
14 C 68
34 S 69 GOOG 2700 1
34 C 69
15 B 70 GOOG 2700 1
15 C 70
35 S 71 GOOG 2700 1
35 C 71
16 B 72 GOOG 2700 1
16 C 72
36 S 73 GOOG 2700 1
36 C 73
17 B 74 GOOG 2700 1
17 C 74
37 S 75 GOOG 2700 1
37 C 75
18 B 76 GOOG 2700 1
18 C 76
38 S 77 GOOG 2700 1
38 C 77
19 B 78 GOOG 2700 1
19 C 78
39 S 79 GOOG 2700 1
39 C 79
0 B 80 GOOG 2700 1
0 C 80
20 S 81 GOOG 2700 1
20 C 81
1 B 82 GOOG 2700 1
1 C 82
21 S 83 GOOG 2700 1
21 C 83
2 B 84 GOOG 2700 1
2 C 84
22 S 85 GOOG 2700 1
22 C 85
3 B 86 GOOG 2700 1
3 C 86
23 S 87 GOOG 2700 1
23 C 87
4 B 88 GOOG 2700 1
4 C 88
24 S 89 GOOG 2700 1
24 C 89
5 B 90 GOOG 2700 1
5 C 90
25 S 91 GOOG 2700 1
25 C 91
6 B 92 GOOG 2700 1
6 C 92
26 S 93 GOOG 2700 1
26 C 93
7 B 94 GOOG 2700 1
7 C 94
27 S 95 GOOG 2700 1
27 C 95
8 B 96 GOOG 2700 1
8 C 96
28 S 97 GOOG 2700 1
28 C 97
9 B 98 GOOG 2700 1
9 C 98
29 S 99 GOOG 2700 1
29 C 99
10 B 100 GOOG 2700 1
10 C 100
30 S 101 GOOG 2700 1
30 C 101
11 B 102 GOOG 2700 1
11 C 102
31 S 103 GOOG 2700 1
31 C 103
12 B 104 GOOG 2700 1
12 C 104
32 S 105 GOOG 2700 1
32 C 105
13 B 106 GOOG 2700 1
13 C 106
33 S 107 GOOG 2700 1
33 C 107
14 B 108 GOOG 2700 1
14 C 108
34 S 109 GOOG 2700 1
34 C 109
15 B 110 GOOG 2700 1
15 C 110
35 S 111 GOOG 2700 1
35 C 111
16 B 112 GOOG 2700 1
16 C 112
36 S 113 GOOG 2700 1
36 C 113
17 B 114 GOOG 2700 1
17 C 114
37 S 115 GOOG 2700 1
37 C 115
18 B 116 GOOG 2700 1
18 C 116
38 S 117 GOOG 2700 1
38 C 117
19 B 118 GOOG 2700 1
19 C 118
39 S 119 GOOG 2700 1
39 C 119
0 B 120 GOOG 2700 1
0 C 120
20 S 121 GOOG 2700 1
20 C 121
1 B 122 GOOG 2700 1
1 C 122
21 S 123 GOOG 2700 1
21 C 123
2 B 124 GOOG 2700 1
2 C 124
22 S 125 GOOG 2700 1
22 C 125
3 B 126 GOOG 2700 1
3 C 126
23 S 127 GOOG 2700 1
23 C 127
4 B 128 GOOG 2700 1
4 C 128
24 S 129 GOOG 2700 1
24 C 129
5 B 130 GOOG 2700 1
5 C 130
25 S 131 GOOG 2700 1
25 C 131
6 B 132 GOOG 2700 1
6 C 132
26 S 133 GOOG 2700 1
26 C 133
7 B 134 GOOG 2700 1
7 C 134
27 S 135 GOOG 2700 1
27 C 135
8 B 136 GOOG 2700 1
8 C 136
28 S 137 GOOG 2700 1
28 C 137
9 B 138 GOOG 2700 1
9 C 138
29 S 139 GOOG 2700 1
29 C 139
10 B 140 GOOG 2700 1
10 C 140
30 S 141 GOOG 2700 1
30 C 141
11 B 142 GOOG 2700 1
11 C 142
31 S 143 GOOG 2700 1
31 C 143
12 B 144 GOOG 2700 1
12 C 144
32 S 145 GOOG 2700 1
32 C 145
13 B 146 GOOG 2700 1
13 C 146
33 S 147 GOOG 2700 1
33 C 147
14 B 148 GOOG 2700 1
14 C 148
34 S 149 GOOG 2700 1
34 C 149
15 B 150 GOOG 2700 1
15 C 150
35 S 151 GOOG 2700 1
35 C 151
16 B 152 GOOG 2700 1
16 C 152
36 S 153 GOOG 2700 1
36 C 153
17 B 154 GOOG 2700 1
17 C 154
37 S 155 GOOG 2700 1
37 C 155
18 B 156 GOOG 2700 1
18 C 156
38 S 157 GOOG 2700 1
38 C 157
19 B 158 GOOG 2700 1
19 C 158
39 S 159 GOOG 2700 1
39 C 159
0 B 160 GOOG 2700 1
0 C 160
20 S 161 GOOG 2700 1
20 C 161
1 B 162 GOOG 2700 1
1 C 162
21 S 163 GOOG 2700 1
21 C 163
2 B 164 GOOG 2700 1
2 C 164
22 S 165 GOOG 2700 1
22 C 165
3 B 166 GOOG 2700 1
3 C 166
23 S 167 GOOG 2700 1
23 C 167
4 B 168 GOOG 2700 1
4 C 168
24 S 169 GOOG 2700 1
24 C 169
5 B 170 GOOG 2700 1
5 C 170
25 S 171 GOOG 2700 1
25 C 171
6 B 172 GOOG 2700 1
6 C 172
26 S 173 GOOG 2700 1
26 C 173
7 B 174 GOOG 2700 1
7 C 174
27 S 175 GOOG 2700 1
27 C 175
8 B 176 GOOG 2700 1
8 C 176
28 S 177 GOOG 2700 1
28 C 177
9 B 178 GOOG 2700 1
9 C 178
29 S 179 GOOG 2700 1
29 C 179
10 B 180 GOOG 2700 1
10 C 180
30 S 181 GOOG 2700 1
30 C 181
11 B 182 GOOG 2700 1
11 C 182
31 S 183 GOOG 2700 1
31 C 183
12 B 184 GOOG 2700 1
12 C 184
32 S 185 GOOG 2700 1
32 C 185
13 B 186 GOOG 2700 1
13 C 186
33 S 187 GOOG 2700 1
33 C 187
14 B 188 GOOG 2700 1
14 C 188
34 S 189 GOOG 2700 1
34 C 189
15 B 190 GOOG 2700 1
15 C 190
35 S 191 GOOG 2700 1
35 C 191
16 B 192 GOOG 2700 1
16 C 192
36 S 193 GOOG 2700 1
36 C 193
17 B 194 GOOG 2700 1
17 C 194
37 S 195 GOOG 2700 1
37 C 195
18 B 196 GOOG 2700 1
18 C 196
38 S 197 GOOG 2700 1
38 C 197
19 B 198 GOOG 2700 1
19 C 198
39 S 199 GOOG 2700 1
39 C 199
0 B 200 GOOG 2700 1
0 C 200
20 S 201 GOOG 2700 1
20 C 201
1 B 202 GOOG 2700 1
1 C 202
21 S 203 GOOG 2700 1
21 C 203
2 B 204 GOOG 2700 1
2 C 204
22 S 205 GOOG 2700 1
22 C 205
3 B 206 GOOG 2700 1
3 C 206
23 S 207 GOOG 2700 1
23 C 207
4 B 208 GOOG 2700 1
4 C 208
24 S 209 GOOG 2700 1
24 C 209
5 B 210 GOOG 2700 1
5 C 210
25 S 211 GOOG 2700 1
25 C 211
6 B 212 GOOG 2700 1
6 C 212
26 S 213 GOOG 2700 1
26 C 213
7 B 214 GOOG 2700 1
7 C 214
27 S 215 GOOG 2700 1
27 C 215
8 B 216 GOOG 2700 1
8 C 216
28 S 217 GOOG 2700 1
28 C 217
9 B 218 GOOG 2700 1
9 C 218
29 S 219 GOOG 2700 1
29 C 219
10 B 220 GOOG 2700 1
10 C 220
30 S 221 GOOG 2700 1
30 C 221
11 B 222 GOOG 2700 1
11 C 222
31 S 223 GOOG 2700 1
31 C 223
12 B 224 GOOG 2700 1
12 C 224
32 S 225 GOOG 2700 1
32 C 225
13 B 226 GOOG 2700 1
13 C 226
33 S 227 GOOG 2700 1
33 C 227
14 B 228 GOOG 2700 1
14 C 228
34 S 229 GOOG 2700 1
34 C 229
15 B 230 GOOG 2700 1
15 C 230
35 S 231 GOOG 2700 1
35 C 231
16 B 232 GOOG 2700 1
16 C 232
36 S 233 GOOG 2700 1
36 C 233
17 B 234 GOOG 2700 1
17 C 234
37 S 235 GOOG 2700 1
37 C 235
18 B 236 GOOG 2700 1
18 C 236
38 S 237 GOOG 2700 1
38 C 237
19 B 238 GOOG 2700 1
19 C 238
39 S 239 GOOG 2700 1
39 C 239
0 B 240 GOOG 2700 1
0 C 240
20 S 241 GOOG 2700 1
20 C 241
1 B 242 GOOG 2700 1
1 C 242
21 S 243 GOOG 2700 1
21 C 243
2 B 244 GOOG 2700 1
2 C 244
22 S 245 GOOG 2700 1
22 C 245
3 B 246 GOOG 2700 1
3 C 246
23 S 247 GOOG 2700 1
23 C 247
4 B 248 GOOG 2700 1
4 C 248
24 S 249 GOOG 2700 1
24 C 249
5 B 250 GOOG 2700 1
5 C 250
25 S 251 GOOG 2700 1
25 C 251
6 B 252 GOOG 2700 1
6 C 252
26 S 253 GOOG 2700 1
26 C 253
7 B 254 GOOG 2700 1
7 C 254
27 S 255 GOOG 2700 1
27 C 255
8 B 256 GOOG 2700 1
8 C 256
28 S 257 GOOG 2700 1
28 C 257
9 B 258 GOOG 2700 1
9 C 258
29 S 259 GOOG 2700 1
29 C 259
10 B 260 GOOG 2700 1
10 C 260
30 S 261 GOOG 2700 1
30 C 261
11 B 262 GOOG 2700 1
11 C 262
31 S 263 GOOG 2700 1
31 C 263
12 B 264 GOOG 2700 1
12 C 264
32 S 265 GOOG 2700 1
32 C 265
13 B 266 GOOG 2700 1
13 C 266
33 S 267 GOOG 2700 1
33 C 267
14 B 268 GOOG 2700 1
14 C 268
34 S 269 GOOG 2700 1
34 C 269
15 B 270 GOOG 2700 1
